<?xml version="1.0"?>
<!-- <robot name="tortoisebot"> -->
<robot xmlns:xacro="http://www.ros.org/wiki/xacro" name="tortoisebot">

    <!-- This will be the main body of the tortoise bot -->
    <link name="base_link">
        <visual>
            <geometry>
                <box size="0.6 0.3 0.3" />
            </geometry>
            <material name="silver">
                <color rgba="0.75 0.75 0.75 1" />
            </material>
        </visual>
        <collision>
            <geometry>
                <box size="0.6 0.3 0.3" />
            </geometry>
        </collision>
        <inertial>
            <mass value="1.0" />
            <inertia ixx="0.015" iyy="0.0375" izz="0.0375" ixy="0" ixz="0" iyz="0" />
        </inertial>
    </link>
    <!-- Define front caster -->
    <link name="front_caster">
        <visual>
            <geometry>
                <box size="0.1 0.1 0.3" />
            </geometry>
            <material name="silver" />
        </visual>
        <collision>
            <geometry>
                <box size="0.1 0.1 0.3" />
            </geometry>
        </collision>
        <inertial>
            <mass value="0.1" />
            <inertia ixx="0.00083" iyy="0.00083" izz="0.000167" ixy="0" ixz="0" iyz="0" />
        </inertial>
    </link>
    <!-- Define joint between front caster and main body -->
    <joint name="front_caster_joint" type="continuous">
        <axis xyz="0 0 1" />
        <parent link="base_link" />
        <child link="front_caster" />
        <origin rpy="0 0 0" xyz="0.3 0 0" />
    </joint>

    <!-- Add front wheel and joint -->
    <link name="front_wheel">
        <visual>
            <geometry>
                <cylinder length="0.05" radius="0.035" />
            </geometry>
            <material name="black" />
        </visual>
        <collision>
            <geometry>
                <cylinder length="0.05" radius="0.035" />
            </geometry>
        </collision>
        <inertial>
            <mass value="0.1" />
            <inertia ixx="5.1458e-5" iyy="5.1458e-5" izz="6.125e-5" ixy="0" ixz="0" iyz="0" />
        </inertial>
    </link>
    <joint name="front_wheel_joint" type="continuous">
        <axis xyz="0 0 1" />
        <parent link="front_caster" />
        <child link="front_wheel" />
        <!-- rotate by -90 deg around the x axis -->
        <origin rpy="-1.5708 0 0" xyz="0.05 0 -.15" />
    </joint>

    <!-- Add rear wheels -->
    <link name="right_wheel">
        <visual>
            <geometry>
                <cylinder length="0.05" radius="0.035" />
            </geometry>
            <material name="black">
                <color rgba="0 0 0 1" />
            </material>
        </visual>
        <collision>
            <geometry>
                <cylinder length="0.05" radius="0.035" />
            </geometry>
        </collision>
        <inertial>
            <mass value="0.1" />
            <inertia ixx="5.1458e-5" iyy="5.1458e-5" izz="6.125e-5" ixy="0" ixz="0" iyz="0" />
        </inertial>
    </link>
    <joint name="right_wheel_joint" type="continuous">
        <axis xyz="0 0 1" />
        <parent link="base_link" />
        <child link="right_wheel" />
        <origin rpy="-1.5708 0 0" xyz="-0.2825 -0.125 -.15" />
    </joint>

    <link name="left_wheel">
        <visual>
            <geometry>
                <cylinder length="0.05" radius="0.035" />
            </geometry>
            <material name="black" />
        </visual>
        <collision>
            <geometry>
                <cylinder length="0.05" radius="0.035" />
            </geometry>
        </collision>
        <inertial>
            <mass value="0.1" />
            <inertia ixx="5.1458e-5" iyy="5.1458e-5" izz="6.125e-5" ixy="0" ixz="0" iyz="0" />
        </inertial>
    </link>
    <joint name="left_wheel_joint" type="continuous">
        <axis xyz="0 0 1" />
        <parent link="base_link" />
        <child link="left_wheel" />
        <origin rpy="-1.5708 0 0" xyz="-0.2825 0.125 -.15" />
    </joint>

    <!-- Mount Ouster OS1-64 LiDAR -->
    <xacro:include filename="$(find ouster_description)/urdf/OS1-64.urdf.xacro" />
    <OS1-64 parent="base_link" name="os1_sensor" hz="10" samples="220">
        <origin xyz="0 0 1.2" rpy="0 0 0" />
    </OS1-64>

    <!-- Load differential drive plugin -->
    <gazebo>
        <plugin name="differential_drive_controller" filename="libgazebo_ros_diff_drive.so">
            <leftJoint>left_wheel_joint</leftJoint>
            <rightJoint>right_wheel_joint</rightJoint>
            <robotBaseFrame>base_link</robotBaseFrame>
            <wheelSeparation>0.25</wheelSeparation>
            <wheelDiameter>0.07</wheelDiameter>
            <publishWheelJointState>true</publishWheelJointState>
        </plugin>
    </gazebo>

    <!-- GPS Sensor -->
    <gazebo>
        <plugin name="gps_sensor" filename="libhector_gazebo_ros_gps.so">
            <alwaysOn>1</alwaysOn>
            <updateRate>10.0</updateRate>
            <robotNamespace> gps </robotNamespace>
            <bodyName>base_link</bodyName>
            <robotBaseFrame>base_link</robotBaseFrame>
            <topicName>/fix</topicName>
            <velocityTopicName>/fix_velocity</velocityTopicName>
            <drift>0.0 0.0 0.0</drift>
            <gaussianNoise>0.5 0.5 0.5</gaussianNoise>
            <velocityDrift>0 0 0</velocityDrift>
            <velocityGaussianNoise>0.01 0.01 0.01</velocityGaussianNoise>
        </plugin>
    </gazebo>
    <!-- TRUE GPS Sensor -->
    <!--<gazebo>
        <plugin name="true_gps" filename="libhector_gazebo_ros_gps.so">
            <alwaysOn>1</alwaysOn>
            <updateRate>10.0</updateRate>
            <bodyName>base_footprint</bodyName>
            <robotBaseFrame>base_link</robotBaseFrame>
            <topicName>true_fix</topicName>
            <velocityTopicName>true_fix_velocity</velocityTopicName>
            <drift>0 0 0</drift>
            <gaussianNoise>0 0 0 </gaussianNoise>
            <velocityDrift>0 0 0</velocityDrift>
            <velocityGaussianNoise>0 0 0</velocityGaussianNoise>
        </plugin>
    </gazebo> -->
</robot>
